Workbook

Sheet Start Here
B2: Maximo Starter Glossary: Full Term Map
B3: Content plan for an open, plain-English Maximo glossary and learning site. Built around one fictional organization so every example connects.
B5: What this is | C5: The complete list of terms for the site, grouped into 14 modules, with a first-draft definition, where it lives in Maximo, a worked example from Riverbend Water, related terms, common misconceptions and version notes.
B6: Total terms | C6: =COUNTA('Term Map'!D2:D319) -> 318
B7: Verified so far | C7: =COUNTIF('Term Map'!N2:N319,"Verified")+COUNTIF('Term Map'!N2:N319,"Published") -> 0
B8: Percent verified | C8: =IFERROR(C7/C6,0) -> 0
B9: How to use it | C9: 1. Read the Riverbend Water tab first so the examples make sense. 2. Work through the Term Map, rewriting each definition in your own voice. The drafts are a starting point, not the final copy. 3. Have a hands-on Maximo practitioner check each row against IBM Docs for your target version, then set Review Status to Verified. 4. Use the Learning Paths tab to build guided tracks on the site. 5. The Page Slug column gives a ready-made URL for each term page.
B10: Review Status values | C10: Not started > Drafted > In review > Verified > Published. Every row starts as Drafted.
B11: Columns you edit | C11: Review Status, Reviewer, Reviewer Notes, and any wording you want to change. Everything else is reference content.
B12: Example row | C12: M03-005 'Work Order Lifecycle / Status Flow' shows the expected depth: definition, status codes, a Riverbend example, related terms and a misconception.
B13: Accuracy note | C13: Version facts were checked against IBM sources in October 2026 (see Sources tab). Field names, statuses, licensing values and app availability can change between releases and are configurable per customer, so confirm against IBM Docs for the version you write about.
B14: Disclaimer for the site | C14: Independent community resource. Not affiliated with or endorsed by IBM. IBM, Maximo and related names are trademarks of IBM Corp. Riverbend Water Authority is fictional.

Sheet Term Map
A1: ID | B1: Module | C1: Sub-area | D1: Term | E1: Field / Code | F1: Plain-English Definition | G1: Where in Maximo | H1: Riverbend Water Example | I1: Related Terms | J1: Common Misconception | K1: Difficulty | L1: Version Note (7.6 / MAS) | M1: Verify In (IBM Docs area) | N1: Review Status | O1: Reviewer | P1: Reviewer Notes | Q1: Page Slug
A2: M01-001 | B2: 01 Foundations and Structure | C2: Multisite structure | D2: Organization | E2: ORGID | F2: The top level of how a company is set up in Maximo. An organization holds the financial rules: base currency, general ledger structure, and many default options that every site under it follows. | G2: Organizations app (Administration) | H2: Riverbend Water Authority is one organization, RWA, with Canadian dollars as its base currency. | I2: Site; Item Set; Company Set; Base Currency; GL Account | J2: People often think an organization is just a label. It actually controls financial behavior, so splitting one company into several organizations has real consequences. | K2: Beginner | L2: Same concept in 7.6 and MAS. | M2: IBM Docs > Maximo Manage > Administering > Organizations and sites | N2: Drafted | Q2: organization
A3: M01-002 | B3: 01 Foundations and Structure | C3: Multisite structure | D3: Site | E3: SITEID | F3: An operational place that belongs to an organization, like a plant, campus or yard. Most day to day records, including work orders, assets and storeroom inventory, are stored at the site level. | G3: Organizations app, Sites action | H3: RWA has three sites: TP1 (Riverbend Treatment Plant), DIST (Distribution Network) and FLEET (Fleet Yard). | I3: Organization; Default Insert Site; Multisite | J3: A site is not the same as a location. A site is a top-level bucket, and locations are the places inside it. | K3: Beginner | M3: IBM Docs > Maximo Manage > Administering > Organizations and sites | N3: Drafted | Q3: site
A4: M01-003 | B4: 01 Foundations and Structure | C4: Multisite structure | D4: Item Set | E4: ITEMSETID | F4: A shared catalog of items and tools that one or more organizations can use. It lets several organizations share the same item numbers and descriptions. | G4: Sets app | H4: RWA uses the item set RWAITEMS, so seal kit 1001-SEAL means the same thing at every site. | I4: Item Master; Company Set; Organization | J4: Item sets hold the item definition only. Stock levels and costs live at the storeroom level, not in the item set. | K4: Intermediate | M4: IBM Docs > Maximo Manage > Administering > Organizations and sites | N4: Drafted | Q4: item-set
A5: M01-004 | B5: 01 Foundations and Structure | C5: Multisite structure | D5: Company Set | E5: COMPANYSETID | F5: A shared list of vendors, manufacturers and other companies that organizations can use. Like item sets, it avoids keeping duplicate vendor records. | G5: Sets app; Company Master app | H5: Northshore Pump Supply is set up once in the RWA company set and used for purchasing at all three sites. | I5: Company / Vendor | K5: Intermediate | M5: IBM Docs > Maximo Manage > Administering > Organizations and sites | N5: Drafted | Q5: company-set
A6: M01-005 | B6: 01 Foundations and Structure | C6: Multisite structure | D6: Multisite | F6: Maximo's ability to run many sites and organizations in one system while keeping data separated where it needs to be. Security, numbering and defaults can all be controlled by site. | G6: Organizations app; Security Groups app | H6: A planner at TP1 only sees TP1 work orders, while the asset manager at head office sees all three sites. | I6: Organization; Site; Security Group; Site-level vs Org-level vs System-level Object | K6: Intermediate | M6: IBM Docs > Maximo Manage > Administering > Organizations and sites | N6: Drafted | Q6: multisite
A7: M01-006 | B7: 01 Foundations and Structure | C7: Multisite structure | D7: Default Insert Site | F7: The site that new records are automatically created in for a user. It is set on each user's profile and saves users from picking a site every time. | G7: Users app; user profile (Default Information) | H7: Ana, a TP1 planner, has TP1 as her default insert site, so every new work order she creates lands at the plant. | I7: Site; User; Person | J7: If a user creates records at the wrong site, the default insert site is the first thing to check. | K7: Beginner | M7: IBM Docs > Maximo Manage > Administering > Organizations and sites | N7: Drafted | Q7: default-insert-site
A8: M01-007 | B8: 01 Foundations and Structure | C8: Multisite structure | D8: Site-level vs Org-level vs System-level Object | F8: Every record type in Maximo belongs at a certain level. Work orders are site-level, chart of account settings are org-level, and things like users and domains are system-level. | G8: Database Configuration app (Level field on each object) | H8: Two sites can each have a work order number 1001 because work orders are site-level, but there is only one user named ANAPLANNER. | I8: Organization; Site; Database Configuration | K8: Advanced | M8: IBM Docs > Maximo Manage > Administering > Organizations and sites | N8: Drafted | Q8: site-level-vs-org-level-vs-system-level-object
A9: M01-008 | B9: 01 Foundations and Structure | C9: Multisite structure | D9: Base Currency | F9: The main currency an organization uses for its financial records. Transactions in other currencies are converted to it using exchange rates. | G9: Organizations app; Currency Code app | H9: RWA's base currency is CAD. A pump bought in USD is converted to CAD on the PO. | I9: Currency Code / Exchange Rate; Organization | K9: Intermediate | M9: IBM Docs > Maximo Manage > Administering > Organizations and sites | N9: Drafted | Q9: base-currency
A10: M01-009 | B10: 01 Foundations and Structure | C10: Record basics | D10: Application | F10: A screen or set of screens in Maximo built around one main type of record, such as Work Order Tracking or Assets. Users open applications from the navigator menu. | G10: Navigator / side menu | H10: A technician opens the Work Order Tracking application to see open jobs. | I10: Module; Object (Maximo Business Object / MBO); Start Center; Role-based Application | K10: Beginner | L10: In MAS 9.1 and later, a new unified navigation bar organizes applications across the suite. | M10: IBM Docs > Maximo Manage > Administering > Organizations and sites | N10: Drafted | Q10: application
A11: M01-010 | B11: 01 Foundations and Structure | C11: Record basics | D11: Module | F11: A group of related applications in the menu, such as Work Orders, Inventory or Purchasing. | G11: Navigator / side menu | H11: The Inventory module includes Item Master, Inventory, Storerooms and Issues and Transfers. | I11: Application | K11: Beginner | M11: IBM Docs > Maximo Manage > Administering > Organizations and sites | N11: Drafted | Q11: module
A12: M01-011 | B12: 01 Foundations and Structure | C12: Record basics | D12: Record | F12: A single entry in an application, like one asset, one work order or one purchase order. | G12: All applications | H12: Work order 50231 for the P-101 seal leak is one record. | I12: Application; Object (Maximo Business Object / MBO); Status | K12: Beginner | M12: IBM Docs > Maximo Manage > Administering > Organizations and sites | N12: Drafted | Q12: record
A13: M01-012 | B13: 01 Foundations and Structure | C13: Record basics | D13: Status | E13: STATUS | F13: The stage a record is in, which controls what can be done with it next. Most major records have their own list of statuses and many keep a full status history. | G13: Change Status action in most applications | H13: Work order 50231 moves from WAPPR to APPR to INPRG to COMP to CLOSE. | I13: Synonym Domain; Work Order Lifecycle / Status Flow; Work Order Status History | J13: Status values can be renamed for users (synonyms), but Maximo's logic runs on the internal value underneath. | K13: Beginner | M13: IBM Docs > Maximo Manage > Administering > Organizations and sites | N13: Drafted | Q13: status
A14: M01-013 | B14: 01 Foundations and Structure | C14: Record basics | D14: Long Description | F14: A larger free-text field attached to many description fields, used for detailed notes that do not fit in the short description. | G14: Long description icon next to a Description field | H14: The work order's short description says 'P-101 seal leaking' and the long description explains when and where it was spotted. | I14: Work Log; Attachments | K14: Beginner | M14: IBM Docs > Maximo Manage > Administering > Organizations and sites | N14: Drafted | Q14: long-description
A15: M01-014 | B15: 01 Foundations and Structure | C15: Record basics | D15: Attachments | E15: DOCLINKS | F15: Files or URLs linked to a record, like manuals, photos, drawings or permits. Attachments can be organized into folders and copied between records. | G15: Attachments section on most applications | H15: The P-101 pump manual PDF is attached to the asset and automatically shows on its work orders. | I15: Long Description; Work Log | K15: Beginner | L15: Older docs refer to this feature as Doclinks. | M15: IBM Docs > Maximo Manage > Administering > Organizations and sites | N15: Drafted | Q15: attachments
A16: M01-015 | B16: 01 Foundations and Structure | C16: Record basics | D16: Work Log | E16: WORKLOG | F16: A running set of notes on a record such as a work order or service request, used to record updates, findings and communication over time. | G16: Log tab or Work Log section | H16: The mechanic adds a log entry: 'Seal faces scored, replaced with kit 1001-SEAL.' | I16: Long Description | K16: Beginner | M16: IBM Docs > Maximo Manage > Administering > Organizations and sites | N16: Drafted | Q16: work-log
A17: M01-016 | B17: 01 Foundations and Structure | C17: Record basics | D17: Query / Saved Query | F17: A search you save so you can reuse it. Queries filter the list of records in an application and can be shared with other users or used on Start Centers. | G17: List tab in each application; Save Query action | H17: Ana saves a query called 'My TP1 backlog' that shows approved work orders at TP1 assigned to the MECH craft. | I17: Start Center; Result Set | K17: Beginner | M17: IBM Docs > Maximo Manage > Administering > Organizations and sites | N17: Drafted | Q17: query-saved-query
A18: M01-017 | B18: 01 Foundations and Structure | C18: Record basics | D18: Start Center | F18: The home page a user sees after logging in. It is made of portlets like result sets, KPIs, bulletin board messages and quick links, and it is assigned through security groups. | G18: Start Center (home page); Start Center Templates | H18: Planners at RWA see their backlog, overdue PMs and a KPI for schedule compliance as soon as they log in. | I18: Result Set; KPI (Key Performance Indicator); Security Group; Work Center | K18: Beginner | M18: IBM Docs > Maximo Manage > Administering > Organizations and sites | N18: Drafted | Q18: start-center
A19: M01-018 | B19: 01 Foundations and Structure | C19: Record basics | D19: Work Center | F19: A simplified, role-focused screen in Maximo designed for specific jobs like technician, supervisor or inventory clerk. Work Centers were the first step toward the newer role-based applications. | G19: Work Centers (from Start Center) | I19: Role-based Application; Start Center | K19: Intermediate | L19: Introduced in later 7.6 releases. In MAS, role-based applications built on the Maximo Application Framework carry this idea forward. | M19: IBM Docs > Maximo Manage > Administering > Organizations and sites | N19: Drafted | Q19: work-center
A20: M01-019 | B20: 01 Foundations and Structure | C20: Record basics | D20: Bulletin Board | F20: A place for posting announcements that show on users' Start Centers, targeted by site, organization or person group. | G20: Bulletin Board app | H20: RWA posts 'Intake channel closed for inspection Monday' to all TP1 users. | I20: Start Center; Communication Template | K20: Beginner | M20: IBM Docs > Maximo Manage > Administering > Organizations and sites | N20: Drafted | Q20: bulletin-board
A21: M02-001 | B21: 02 Assets and Locations | C21: Locations | D21: Location | E21: LOCATION | F21: A place where an asset sits or work happens, defined by its function rather than the equipment in it. A location stays the same even when the asset inside it gets swapped out. | G21: Locations app | H21: TP1-INTAKE-PS is the raw water intake pump position. The pump in it can change; the position does not. | I21: Asset; Location Hierarchy; System (Location System); Location Type | J21: The classic mix-up: a location is the job the equipment does or the spot it lives in, while an asset is the physical thing you can pick up and move. | K21: Beginner | M21: IBM Docs > Maximo Manage > Assets / Locations | N21: Drafted | Q21: location
A22: M02-002 | B22: 02 Assets and Locations | C22: Locations | D22: Location Type | E22: TYPE | F22: A setting that tells Maximo what a location is used for. Common types include OPERATING, STOREROOM, REPAIR, SALVAGE, VENDOR, COURIER and LABOR. | G22: Locations app (Type field) | H22: CENTRAL is a STOREROOM location, TP1-INTAKE-PS is an OPERATING location and REPAIR-SHOP is a REPAIR location. | I22: Location; Storeroom; Repair Facility | K22: Intermediate | M22: IBM Docs > Maximo Manage > Assets / Locations | N22: Drafted | Q22: location-type
A23: M02-003 | B23: 02 Assets and Locations | C23: Locations | D23: Location Hierarchy | F23: The parent and child structure of locations that shows how places are organized, from a whole site down to individual equipment positions. | G23: Locations app, Systems section | H23: TP1 > TP1-INTAKE > TP1-INTAKE-PS > P-101 position. | I23: System (Location System); Primary System; Asset Hierarchy | K23: Beginner | M23: IBM Docs > Maximo Manage > Assets / Locations | N23: Drafted | Q23: location-hierarchy
A24: M02-004 | B24: 02 Assets and Locations | C24: Locations | D24: System (Location System) | E24: SYSTEMID | F24: A named hierarchy that locations belong to. One location can belong to several systems, which lets you view the same places from different angles, such as by process or by electrical feed. | G24: Locations app; Systems action | H24: TP1 has a PROCESS system that follows how water flows and an ELECTRICAL system that follows the power feeds. | I24: Location Hierarchy; Primary System; Network (Location Network) | K24: Intermediate | M24: IBM Docs > Maximo Manage > Assets / Locations | N24: Drafted | Q24: system-location-system
A25: M02-005 | B25: 02 Assets and Locations | C25: Locations | D25: Primary System | F25: The main location hierarchy for a site. Each site has exactly one, and it is the default view of where everything fits. | G25: Locations app (System field marked Primary) | H25: PROCESS is RWA TP1's primary system. | I25: System (Location System); Location Hierarchy | K25: Intermediate | M25: IBM Docs > Maximo Manage > Assets / Locations | N25: Drafted | Q25: primary-system
A26: M02-006 | B26: 02 Assets and Locations | C26: Locations | D26: Network (Location Network) | F26: A type of location system where a location can have more than one parent, useful for pipe networks or utilities where things connect in more than one direction. | G26: Locations app (Network systems) | H26: The DIST water main network lets a valve connect to two upstream mains. | I26: System (Location System); Linear Asset | K26: Advanced | M26: IBM Docs > Maximo Manage > Assets / Locations | N26: Drafted | Q26: network-location-network
A27: M02-007 | B27: 02 Assets and Locations | C27: Locations | D27: Repair Facility | F27: A location of type REPAIR where broken rotating assets are sent to be fixed. Work orders can be raised against the repair facility. | G27: Locations app; Work Order Tracking (Repair Facility field) | H27: A failed motor is moved to REPAIR-SHOP, rebuilt, then returned to the CENTRAL storeroom. | I27: Rotating Asset / Rotating Item; Location Type | K27: Advanced | M27: IBM Docs > Maximo Manage > Assets / Locations | N27: Drafted | Q27: repair-facility
A28: M02-008 | B28: 02 Assets and Locations | C28: Assets | D28: Asset | E28: ASSETNUM | F28: A physical piece of equipment or property that you want to track, maintain and cost, like a pump, motor, vehicle or HVAC unit. Each asset has its own history of work, costs, meters and failures. | G28: Assets app | H28: P-101 is a 250 HP centrifugal raw water pump. All of its repairs, PMs and costs roll up to this record. | I28: Location; Asset Hierarchy; Rotating Asset / Rotating Item; Asset Status | J28: Not everything needs to be an asset. If you will never maintain, cost or report on it individually, tracking it as an asset just adds noise. | K28: Beginner | M28: IBM Docs > Maximo Manage > Assets / Locations | N28: Drafted | Q28: asset
A29: M02-009 | B29: 02 Assets and Locations | C29: Assets | D29: Asset Hierarchy | E29: PARENT | F29: The parent and child relationships between assets, showing what is part of what. Costs can roll up from children to parents. | G29: Assets app (Parent field; Children view) | H29: P-101 (pump) is the parent of M-101 (motor) and C-101 (coupling). | I29: Location Hierarchy; Rolled-up Costs; Asset | J29: An asset hierarchy and a location hierarchy are separate structures. Many sites build both, and they often look similar but serve different purposes. | K29: Beginner | M29: IBM Docs > Maximo Manage > Assets / Locations | N29: Drafted | Q29: asset-hierarchy
A30: M02-010 | B30: 02 Assets and Locations | C30: Assets | D30: Asset Status | E30: STATUS | F30: The current state of an asset. Common out-of-the-box values include NOT READY, OPERATING and DECOMMISSIONED, and organizations often add synonyms for their own needs. | G30: Assets app, Change Status action | H30: When P-101 is installed and commissioned, it moves from NOT READY to OPERATING. | I30: Asset Downtime; Status | J30: An asset can be OPERATING while it is down for a repair. Whether it is running right now is tracked separately through downtime reporting. | K30: Beginner | M30: IBM Docs > Maximo Manage > Assets / Locations | N30: Drafted | Q30: asset-status
A31: M02-011 | B31: 02 Assets and Locations | C31: Assets | D31: Rotating Asset / Rotating Item | E31: ROTATING | F31: An item that is stocked in a storeroom but also tracked individually as an asset with its own number and history, because it gets installed, removed, repaired and reused. | G31: Item Master (Rotating checkbox); Assets app | H31: Motor M-101 is a rotating item. When it fails it goes to repair, and a spare motor from CENTRAL is installed in its place, each keeping its own history. | I31: Item Master; Condition Code; Repair Facility; Move / Swap / Modify Assets | J31: Rotating assets are counted in both the asset register and inventory balances, which surprises people the first time they reconcile numbers. | K31: Intermediate | M31: IBM Docs > Maximo Manage > Assets / Locations | N31: Drafted | Q31: rotating-asset-rotating-item
A32: M02-012 | B32: 02 Assets and Locations | C32: Assets | D32: Move / Swap / Modify Assets | F32: Actions for moving an asset to another location, swapping one asset for another, or changing its details while keeping its history. | G32: Assets app, Move/Modify Assets and Swap Asset actions | H32: Mechanics swap failed motor M-101 with spare M-117. Maximo records both moves and the date of each. | I32: Rotating Asset / Rotating Item; Asset Status | K32: Intermediate | M32: IBM Docs > Maximo Manage > Assets / Locations | N32: Drafted | Q32: move-swap-modify-assets
A33: M02-013 | B33: 02 Assets and Locations | C33: Assets | D33: Spare Parts (Asset) | F33: A list of items linked to an asset showing which parts are used to maintain it. It helps planners and technicians know exactly what to pull from stores. | G33: Assets app, Spare Parts tab | H33: P-101's spare parts list includes seal kit 1001-SEAL, bearing 2040 and coupling insert 3310. | I33: Item Master; Job Plan Materials / Labor / Services / Tools | K33: Beginner | M33: IBM Docs > Maximo Manage > Assets / Locations | N33: Drafted | Q33: spare-parts-asset
A34: M02-014 | B34: 02 Assets and Locations | C34: Assets | D34: Asset Specifications | F34: Technical attributes stored on an asset, such as horsepower, voltage or flow rate, usually driven by its classification. | G34: Assets app, Specifications tab | H34: P-101's specs show 250 HP, 600 V and a rated flow of 900 m3/h. | I34: Classification; Attribute | K34: Intermediate | M34: IBM Docs > Maximo Manage > Assets / Locations | N34: Drafted | Q34: asset-specifications
A35: M02-015 | B35: 02 Assets and Locations | C35: Assets | D35: Asset Template | F35: A reusable pattern for creating many similar assets with the same specs, spare parts, meters, PMs and other details. | G35: Asset Templates app | H35: RWA builds a template for its standard 40 HP booster pump and creates 12 identical assets for DIST pump stations in one pass. | I35: Asset; Classification; Preventive Maintenance (PM) Record | K35: Intermediate | M35: IBM Docs > Maximo Manage > Assets / Locations | N35: Drafted | Q35: asset-template
A36: M02-016 | B36: 02 Assets and Locations | C36: Assets | D36: Asset Downtime | F36: A record of when an asset was not available, captured by reporting it down and back up. Downtime history feeds availability and reliability reporting. | G36: Assets app or Work Order Tracking, Report Downtime action | H36: P-101 is reported down at 08:15 for the seal repair and back up at 14:40, logging 6.4 hours of downtime. | I36: Availability; MTTR (Mean Time to Repair); Asset Status | K36: Intermediate | M36: IBM Docs > Maximo Manage > Assets / Locations | N36: Drafted | Q36: asset-downtime
A37: M02-017 | B37: 02 Assets and Locations | C37: Assets | D37: Rolled-up Costs | F37: Maintenance costs from child assets and work orders that add up into the parent asset, so you can see the full cost of a system. | G37: Assets app (Cost section; rollup) | H37: Repairs to M-101 and C-101 roll up into P-101's total maintenance cost. | I37: Asset Hierarchy; Planned vs Actual Cost | K37: Intermediate | M37: IBM Docs > Maximo Manage > Assets / Locations | N37: Drafted | Q37: rolled-up-costs
A38: M02-018 | B38: 02 Assets and Locations | C38: Assets | D38: Asset Priority / Criticality | E38: PRIORITY | F38: A rating that shows how important an asset is to operations. It is often used with work order priority to decide what gets done first. | G38: Assets app (Priority field); Maximo Health criticality | H38: P-101 is priority 1 because the plant cannot take in raw water without it. An office HVAC unit is priority 4. | I38: Work Order Priority; Calculated Priority; Criticality Analysis | K38: Beginner | M38: IBM Docs > Maximo Manage > Assets / Locations | N38: Drafted | Q38: asset-priority-criticality
A39: M02-019 | B39: 02 Assets and Locations | C39: Assets | D39: Warranty | F39: Coverage information tied to an asset showing that repairs may be paid for by a vendor. Maximo can warn users when they create work on an asset under warranty. | G39: Assets app; Warranty Contracts app | H39: New motor M-117 is under a two-year manufacturer warranty, so a warning pops up when a work order is created on it. | I39: Warranty Contract; Purchase Contract | K39: Intermediate | M39: IBM Docs > Maximo Manage > Assets / Locations | N39: Drafted | Q39: warranty
A40: M02-020 | B40: 02 Assets and Locations | C40: Assets | D40: Collection | F40: A named group of assets, locations and other records, often used to control which records a group of users can see or work on. | G40: Collections app | H40: The 'DIST pump stations' collection is used to give the distribution crew access to just their equipment. | I40: Security Group; Asset; Location | K40: Advanced | M40: IBM Docs > Maximo Manage > Assets / Locations | N40: Drafted | Q40: collection
...

Sheet Modules
A1: Module | B1: What it covers | C1: Terms | D1: Beginner | E1: Intermediate | F1: Advanced | G1: Verified or Published | H1: % Verified
A2: 01 Foundations and Structure | B2: How Maximo is organized (organizations, sites, sets) and the basics every screen shares: records, statuses, queries, Start Centers. | C2: =COUNTIF('Term Map'!$B$2:$B$319,A2) -> 19 | D2: =COUNTIFS('Term Map'!$B$2:$B$319,A2,'Term Map'!$K$2:$K$319,"Beginner") -> 13 | E2: =COUNTIFS('Term Map'!$B$2:$B$319,A2,'Term Map'!$K$2:$K$319,"Intermediate") -> 5 | F2: =COUNTIFS('Term Map'!$B$2:$B$319,A2,'Term Map'!$K$2:$K$319,"Advanced") -> 1 | G2: =COUNTIFS('Term Map'!$B$2:$B$319,A2,'Term Map'!$N$2:$N$319,"Verified")+COUNTIFS('Term Map'!$B$2:$B$319,A2,'Term Map'!$N$2:$N$319,"Published") -> 0 | H2: =IFERROR(G2/C2,0) -> 0
A3: 02 Assets and Locations | B3: Locations vs assets, hierarchies, systems, rotating assets, classifications, failure codes and meters. | C3: =COUNTIF('Term Map'!$B$2:$B$319,A3) -> 30 | D3: =COUNTIFS('Term Map'!$B$2:$B$319,A3,'Term Map'!$K$2:$K$319,"Beginner") -> 9 | E3: =COUNTIFS('Term Map'!$B$2:$B$319,A3,'Term Map'!$K$2:$K$319,"Intermediate") -> 17 | F3: =COUNTIFS('Term Map'!$B$2:$B$319,A3,'Term Map'!$K$2:$K$319,"Advanced") -> 4 | G3: =COUNTIFS('Term Map'!$B$2:$B$319,A3,'Term Map'!$N$2:$N$319,"Verified")+COUNTIFS('Term Map'!$B$2:$B$319,A3,'Term Map'!$N$2:$N$319,"Published") -> 0 | H3: =IFERROR(G3/C3,0) -> 0
A4: 03 Work Management | B4: Service requests, work orders, the status lifecycle, plans vs actuals, tasks, child work orders, execution and inspections. | C4: =COUNTIF('Term Map'!$B$2:$B$319,A4) -> 27 | D4: =COUNTIFS('Term Map'!$B$2:$B$319,A4,'Term Map'!$K$2:$K$319,"Beginner") -> 18 | E4: =COUNTIFS('Term Map'!$B$2:$B$319,A4,'Term Map'!$K$2:$K$319,"Intermediate") -> 8 | F4: =COUNTIFS('Term Map'!$B$2:$B$319,A4,'Term Map'!$K$2:$K$319,"Advanced") -> 1 | G4: =COUNTIFS('Term Map'!$B$2:$B$319,A4,'Term Map'!$N$2:$N$319,"Verified")+COUNTIFS('Term Map'!$B$2:$B$319,A4,'Term Map'!$N$2:$N$319,"Published") -> 0 | H4: =IFERROR(G4/C4,0) -> 0
A5: 04 Planning: Job Plans, PMs, Routes and Safety | B5: Job plans, preventive maintenance schedules, routes and safety (hazards, precautions, lockout/tagout, permits). | C5: =COUNTIF('Term Map'!$B$2:$B$319,A5) -> 23 | D5: =COUNTIFS('Term Map'!$B$2:$B$319,A5,'Term Map'!$K$2:$K$319,"Beginner") -> 8 | E5: =COUNTIFS('Term Map'!$B$2:$B$319,A5,'Term Map'!$K$2:$K$319,"Intermediate") -> 11 | F5: =COUNTIFS('Term Map'!$B$2:$B$319,A5,'Term Map'!$K$2:$K$319,"Advanced") -> 4 | G5: =COUNTIFS('Term Map'!$B$2:$B$319,A5,'Term Map'!$N$2:$N$319,"Verified")+COUNTIFS('Term Map'!$B$2:$B$319,A5,'Term Map'!$N$2:$N$319,"Published") -> 0 | H5: =IFERROR(G5/C5,0) -> 0
A6: 05 Inventory and Storerooms | B6: Items, storerooms, balances, reservations, issues, returns, transfers, counting, reordering and cost types. | C6: =COUNTIF('Term Map'!$B$2:$B$319,A6) -> 30 | D6: =COUNTIFS('Term Map'!$B$2:$B$319,A6,'Term Map'!$K$2:$K$319,"Beginner") -> 9 | E6: =COUNTIFS('Term Map'!$B$2:$B$319,A6,'Term Map'!$K$2:$K$319,"Intermediate") -> 18 | F6: =COUNTIFS('Term Map'!$B$2:$B$319,A6,'Term Map'!$K$2:$K$319,"Advanced") -> 3 | G6: =COUNTIFS('Term Map'!$B$2:$B$319,A6,'Term Map'!$N$2:$N$319,"Verified")+COUNTIFS('Term Map'!$B$2:$B$319,A6,'Term Map'!$N$2:$N$319,"Published") -> 0 | H6: =IFERROR(G6/C6,0) -> 0
A7: 06 Purchasing and Contracts | B7: Requisitions, RFQs, purchase orders, receiving, invoicing, vendors and the different kinds of contracts. | C7: =COUNTIF('Term Map'!$B$2:$B$319,A7) -> 23 | D7: =COUNTIFS('Term Map'!$B$2:$B$319,A7,'Term Map'!$K$2:$K$319,"Beginner") -> 7 | E7: =COUNTIFS('Term Map'!$B$2:$B$319,A7,'Term Map'!$K$2:$K$319,"Intermediate") -> 11 | F7: =COUNTIFS('Term Map'!$B$2:$B$319,A7,'Term Map'!$K$2:$K$319,"Advanced") -> 5 | G7: =COUNTIFS('Term Map'!$B$2:$B$319,A7,'Term Map'!$N$2:$N$319,"Verified")+COUNTIFS('Term Map'!$B$2:$B$319,A7,'Term Map'!$N$2:$N$319,"Published") -> 0 | H7: =IFERROR(G7/C7,0) -> 0
A8: 07 Labor, Crafts and Scheduling | B8: People, users and labor, crafts, qualifications, calendars, crews and how planning differs from scheduling. | C8: =COUNTIF('Term Map'!$B$2:$B$319,A8) -> 17 | D8: =COUNTIFS('Term Map'!$B$2:$B$319,A8,'Term Map'!$K$2:$K$319,"Beginner") -> 5 | E8: =COUNTIFS('Term Map'!$B$2:$B$319,A8,'Term Map'!$K$2:$K$319,"Intermediate") -> 9 | F8: =COUNTIFS('Term Map'!$B$2:$B$319,A8,'Term Map'!$K$2:$K$319,"Advanced") -> 3 | G8: =COUNTIFS('Term Map'!$B$2:$B$319,A8,'Term Map'!$N$2:$N$319,"Verified")+COUNTIFS('Term Map'!$B$2:$B$319,A8,'Term Map'!$N$2:$N$319,"Published") -> 0 | H8: =IFERROR(G8/C8,0) -> 0
A9: 08 Finance and Cost | B9: GL accounts, financial periods, currencies, planned vs actual cost and life-to-date cost. | C9: =COUNTIF('Term Map'!$B$2:$B$319,A9) -> 12 | D9: =COUNTIFS('Term Map'!$B$2:$B$319,A9,'Term Map'!$K$2:$K$319,"Beginner") -> 1 | E9: =COUNTIFS('Term Map'!$B$2:$B$319,A9,'Term Map'!$K$2:$K$319,"Intermediate") -> 8 | F9: =COUNTIFS('Term Map'!$B$2:$B$319,A9,'Term Map'!$K$2:$K$319,"Advanced") -> 3 | G9: =COUNTIFS('Term Map'!$B$2:$B$319,A9,'Term Map'!$N$2:$N$319,"Verified")+COUNTIFS('Term Map'!$B$2:$B$319,A9,'Term Map'!$N$2:$N$319,"Published") -> 0 | H9: =IFERROR(G9/C9,0) -> 0
A10: 09 Platform, Configuration and Administration | B10: Security, domains, Database Configuration, Application Designer, workflow, escalations, automation scripts and admin tools. | C10: =COUNTIF('Term Map'!$B$2:$B$319,A10) -> 23 | D10: =COUNTIFS('Term Map'!$B$2:$B$319,A10,'Term Map'!$K$2:$K$319,"Beginner") -> 2 | E10: =COUNTIFS('Term Map'!$B$2:$B$319,A10,'Term Map'!$K$2:$K$319,"Intermediate") -> 6 | F10: =COUNTIFS('Term Map'!$B$2:$B$319,A10,'Term Map'!$K$2:$K$319,"Advanced") -> 15 | G10: =COUNTIFS('Term Map'!$B$2:$B$319,A10,'Term Map'!$N$2:$N$319,"Verified")+COUNTIFS('Term Map'!$B$2:$B$319,A10,'Term Map'!$N$2:$N$319,"Published") -> 0 | H10: =IFERROR(G10/C10,0) -> 0
A11: 10 Integration, Data and Reporting | B11: The integration framework, REST API, data loading and quality, BIRT reports, KPIs and analytics. | C11: =COUNTIF('Term Map'!$B$2:$B$319,A11) -> 18 | D11: =COUNTIFS('Term Map'!$B$2:$B$319,A11,'Term Map'!$K$2:$K$319,"Beginner") -> 3 | E11: =COUNTIFS('Term Map'!$B$2:$B$319,A11,'Term Map'!$K$2:$K$319,"Intermediate") -> 4 | F11: =COUNTIFS('Term Map'!$B$2:$B$319,A11,'Term Map'!$K$2:$K$319,"Advanced") -> 11 | G11: =COUNTIFS('Term Map'!$B$2:$B$319,A11,'Term Map'!$N$2:$N$319,"Verified")+COUNTIFS('Term Map'!$B$2:$B$319,A11,'Term Map'!$N$2:$N$319,"Published") -> 0 | H11: =IFERROR(G11/C11,0) -> 0
A12: 11 MAS Platform, Deployment and Licensing | B12: What MAS is, how it differs from 7.6, OpenShift architecture, workspaces, deployment options and AppPoints licensing. | C12: =COUNTIF('Term Map'!$B$2:$B$319,A12) -> 24 | D12: =COUNTIFS('Term Map'!$B$2:$B$319,A12,'Term Map'!$K$2:$K$319,"Beginner") -> 4 | E12: =COUNTIFS('Term Map'!$B$2:$B$319,A12,'Term Map'!$K$2:$K$319,"Intermediate") -> 12 | F12: =COUNTIFS('Term Map'!$B$2:$B$319,A12,'Term Map'!$K$2:$K$319,"Advanced") -> 8 | G12: =COUNTIFS('Term Map'!$B$2:$B$319,A12,'Term Map'!$N$2:$N$319,"Verified")+COUNTIFS('Term Map'!$B$2:$B$319,A12,'Term Map'!$N$2:$N$319,"Published") -> 0 | H12: =IFERROR(G12/C12,0) -> 0
A13: 12 MAS Applications: Monitor, Health, Predict, Mobile, AI | B13: Monitor, Health, Predict, Visual Inspection, Maximo Mobile, Optimizer and the AI features in MAS. | C13: =COUNTIF('Term Map'!$B$2:$B$319,A13) -> 28 | D13: =COUNTIFS('Term Map'!$B$2:$B$319,A13,'Term Map'!$K$2:$K$319,"Beginner") -> 6 | E13: =COUNTIFS('Term Map'!$B$2:$B$319,A13,'Term Map'!$K$2:$K$319,"Intermediate") -> 12 | F13: =COUNTIFS('Term Map'!$B$2:$B$319,A13,'Term Map'!$K$2:$K$319,"Advanced") -> 10 | G13: =COUNTIFS('Term Map'!$B$2:$B$319,A13,'Term Map'!$N$2:$N$319,"Verified")+COUNTIFS('Term Map'!$B$2:$B$319,A13,'Term Map'!$N$2:$N$319,"Published") -> 0 | H13: =IFERROR(G13/C13,0) -> 0
... A15: 14 Maintenance and Reliability Concepts | B15: The maintenance and reliability ideas behind Maximo: strategies, RCM, FMEA, P-F curve, MTBF, MTTR and other metrics. | C15: =COUNTIF('Term Map'!$B$2:$B$319,A15) -> 23 | D15: =COUNTIFS('Term Map'!$B$2:$B$319,A15,'Term Map'!$K$2:$K$319,"Beginner") -> 8 | E15: =COUNTIFS('Term Map'!$B$2:$B$319,A15,'Term Map'!$K$2:$K$319,"Intermediate") -> 12 | F15: =COUNTIFS('Term Map'!$B$2:$B$319,A15,'Term Map'!$K$2:$K$319,"Advanced") -> 3 | G15: =COUNTIFS('Term Map'!$B$2:$B$319,A15,'Term Map'!$N$2:$N$319,"Verified")+COUNTIFS('Term Map'!$B$2:$B$319,A15,'Term Map'!$N$2:$N$319,"Published") -> 0 | H15: =IFERROR(G15/C15,0) -> 0
A16: Total | C16: =SUM(C2:C15) -> 318 | D16: =SUM(D2:D15) -> 94 | E16: =SUM(E2:E15) -> 140 | F16: =SUM(F2:F15) -> 84 | G16: =SUM(G2:G15) -> 0 | H16: =IFERROR(G16/C16,0) -> 0

Sheet Riverbend Water
A1: Riverbend Water Authority (fictional): the one organization used in every example
A2: A mid-sized municipal water utility. Keep these names consistent across the whole site so readers follow one asset through every concept.
A4: Record Type | B4: ID / Name | C4: Description | D4: Parent / Belongs To | E4: Used In (Modules)
A5: Organization | B5: RWA | C5: Riverbend Water Authority. Base currency CAD. | E5: 01, 08
A6: Site | B6: TP1 | C6: Riverbend Treatment Plant | D6: RWA | E6: All
A7: Site | B7: DIST | C7: Distribution Network (mains, valves, pump stations, hydrants) | D7: RWA | E7: 02, 13
A8: Site | B8: FLEET | C8: Fleet Yard (40 service trucks and equipment) | D8: RWA | E8: 13
A9: Item Set | B9: RWAITEMS | C9: Shared item catalog for all RWA sites | D9: RWA | E9: 01, 05
A10: Location System | B10: PROCESS | C10: Primary system at TP1, follows the water treatment process | D10: TP1 | E10: 02
A11: Location System | B11: ELECTRICAL | C11: Secondary system at TP1, follows the power feeds | D11: TP1 | E11: 02
A12: Location | B12: TP1-INTAKE | C12: Raw water intake area | D12: TP1 (PROCESS) | E12: 02
A13: Location | B13: TP1-INTAKE-PS | C13: Raw water intake pump position (where P-101 sits) | D13: TP1-INTAKE | E13: 02, 03
A14: Location | B14: TP1-FILT | C14: Filtration building | D14: TP1 (PROCESS) | E14: 02, 04
A15: Location | B15: TP1-CHEM | C15: Chemical feed room (chlorine hazard) | D15: TP1 (PROCESS) | E15: 04
A16: Location | B16: CENTRAL | C16: Main storeroom at TP1 (type STOREROOM) | D16: TP1 | E16: 05, 06
A17: Location | B17: DIST-STORE | C17: Distribution yard storeroom (type STOREROOM) | D17: DIST | E17: 05
... A31: Item | B31: 2040 | C31: Pump bearing | D31: RWAITEMS / CENTRAL | E31: 05
A32: Job Plan | B32: JP-SEAL-CENT | C32: Replace mechanical seal on centrifugal pump | E32: 04
A33: Job Plan | B33: JP-INSP-PUMP | C33: Quarterly pump inspection | E33: 04
A34: Job Plan | B34: JP-LOTO-PUMP | C34: Lockout steps, nested in other pump job plans | E34: 04
A35: PM | B35: PM-P101-QTR | C35: Quarterly inspection of P-101, 14-day lead time | D35: P-101 | E35: 04
A36: PM | B36: PM-P101-LUBE | C36: Lubrication every 500 run hours | D36: P-101 | E36: 04
A37: Route | B37: RT-TP1-DAILY | C37: Daily operator round: intake, filters, chemical feed, clearwell | D37: TP1 | E37: 04
A38: Safety Plan | B38: SP-PUMP-LOTO | C38: Rotating equipment, stored energy and confined space hazards | E38: 04
A39: Work Order | B39: 50231 | C39: Replace seal on P-101 (CM, priority 1). The main example work order. | D39: P-101 | E39: 03, 05, 08
A40: Work Order | B40: 50400 | C40: TP1 annual shutdown (parent with 37 children) | D40: TP1 | E40: 03, 07
A41: Service Request | B41: 3412 | C41: Water pooling under P-101, reported by an operator | D41: P-101 | E41: 03
A42: Purchase Order | B42: 22014 | C42: 4 x 1001-SEAL from Northshore Pump Supply | D42: CENTRAL | E42: 06
A43: Company | B43: Northshore Pump Supply | C43: Main parts vendor | D43: Company set | E43: 06
A44: Company | B44: Apex Pumps | C44: Manufacturer of P-101 and M-117 | D44: Company set | E44: 06
A45: Craft | B45: MECH / ELEC / INST / OPER | C45: Mechanic, electrician, instrument tech, operator | E45: 07
A46: Person / Labor | B46: Dev Patel (DPATEL) | C46: Journeyman mechanic, does most example jobs | D46: MECH | E46: 03, 07
A47: Person | B47: Ana Moreau | C47: Maintenance planner at TP1 | E47: 01, 03, 07
A48: Person Group | B48: TP1-SUPV | C48: Shift supervisors at TP1 | E48: 07, 09

Sheet Learning Paths
A1: Learning Path | B1: Step | C1: Term | D1: Term ID (linked) | E1: Difficulty (linked) | F1: Module (linked)
A2: 1. Your first week in Maximo | B2: 1 | C2: Organization | D2: =IFERROR(INDEX('Term Map'!$A$2:$A$319,MATCH(C2,'Term Map'!$D$2:$D$319,0)),"Not found") -> M01-001 | E2: =IFERROR(INDEX('Term Map'!$K$2:$K$319,MATCH(C2,'Term Map'!$D$2:$D$319,0)),"") -> Beginner | F2: =IFERROR(INDEX('Term Map'!$B$2:$B$319,MATCH(C2,'Term Map'!$D$2:$D$319,0)),"") -> 01 Foundations and Structure
A3: 1. Your first week in Maximo | B3: 2 | C3: Site | D3: =IFERROR(INDEX('Term Map'!$A$2:$A$319,MATCH(C3,'Term Map'!$D$2:$D$319,0)),"Not found") -> M01-002 | E3: =IFERROR(INDEX('Term Map'!$K$2:$K$319,MATCH(C3,'Term Map'!$D$2:$D$319,0)),"") -> Beginner | F3: =IFERROR(INDEX('Term Map'!$B$2:$B$319,MATCH(C3,'Term Map'!$D$2:$D$319,0)),"") -> 01 Foundations and Structure
A4: 1. Your first week in Maximo | B4: 3 | C4: Location | D4: =IFERROR(INDEX('Term Map'!$A$2:$A$319,MATCH(C4,'Term Map'!$D$2:$D$319,0)),"Not found") -> M02-001 | E4: =IFERROR(INDEX('Term Map'!$K$2:$K$319,MATCH(C4,'Term Map'!$D$2:$D$319,0)),"") -> Beginner | F4: =IFERROR(INDEX('Term Map'!$B$2:$B$319,MATCH(C4,'Term Map'!$D$2:$D$319,0)),"") -> 02 Assets and Locations
A5: 1. Your first week in Maximo | B5: 4 | C5: Asset | D5: =IFERROR(INDEX('Term Map'!$A$2:$A$319,MATCH(C5,'Term Map'!$D$2:$D$319,0)),"Not found") -> M02-008 | E5: =IFERROR(INDEX('Term Map'!$K$2:$K$319,MATCH(C5,'Term Map'!$D$2:$D$319,0)),"") -> Beginner | F5: =IFERROR(INDEX('Term Map'!$B$2:$B$319,MATCH(C5,'Term Map'!$D$2:$D$319,0)),"") -> 02 Assets and Locations
A6: 1. Your first week in Maximo | B6: 5 | C6: Asset Hierarchy | D6: =IFERROR(INDEX('Term Map'!$A$2:$A$319,MATCH(C6,'Term Map'!$D$2:$D$319,0)),"Not found") -> M02-009 | E6: =IFERROR(INDEX('Term Map'!$K$2:$K$319,MATCH(C6,'Term Map'!$D$2:$D$319,0)),"") -> Beginner | F6: =IFERROR(INDEX('Term Map'!$B$2:$B$319,MATCH(C6,'Term Map'!$D$2:$D$319,0)),"") -> 02 Assets and Locations
A7: 1. Your first week in Maximo | B7: 6 | C7: Service Request | D7: =IFERROR(INDEX('Term Map'!$A$2:$A$319,MATCH(C7,'Term Map'!$D$2:$D$319,0)),"Not found") -> M03-001 | E7: =IFERROR(INDEX('Term Map'!$K$2:$K$319,MATCH(C7,'Term Map'!$D$2:$D$319,0)),"") -> Beginner | F7: =IFERROR(INDEX('Term Map'!$B$2:$B$319,MATCH(C7,'Term Map'!$D$2:$D$319,0)),"") -> 03 Work Management
A8: 1. Your first week in Maximo | B8: 7 | C8: Work Order | D8: =IFERROR(INDEX('Term Map'!$A$2:$A$319,MATCH(C8,'Term Map'!$D$2:$D$319,0)),"Not found") -> M03-004 | E8: =IFERROR(INDEX('Term Map'!$K$2:$K$319,MATCH(C8,'Term Map'!$D$2:$D$319,0)),"") -> Beginner | F8: =IFERROR(INDEX('Term Map'!$B$2:$B$319,MATCH(C8,'Term Map'!$D$2:$D$319,0)),"") -> 03 Work Management
A9: 1. Your first week in Maximo | B9: 8 | C9: Work Order Lifecycle / Status Flow | D9: =IFERROR(INDEX('Term Map'!$A$2:$A$319,MATCH(C9,'Term Map'!$D$2:$D$319,0)),"Not found") -> M03-005 | E9: =IFERROR(INDEX('Term Map'!$K$2:$K$319,MATCH(C9,'Term Map'!$D$2:$D$319,0)),"") -> Beginner | F9: =IFERROR(INDEX('Term Map'!$B$2:$B$319,MATCH(C9,'Term Map'!$D$2:$D$319,0)),"") -> 03 Work Management
A10: 1. Your first week in Maximo | B10: 9 | C10: Work Type | D10: =IFERROR(INDEX('Term Map'!$A$2:$A$319,MATCH(C10,'Term Map'!$D$2:$D$319,0)),"Not found") -> M03-006 | E10: =IFERROR(INDEX('Term Map'!$K$2:$K$319,MATCH(C10,'Term Map'!$D$2:$D$319,0)),"") -> Beginner | F10: =IFERROR(INDEX('Term Map'!$B$2:$B$319,MATCH(C10,'Term Map'!$D$2:$D$319,0)),"") -> 03 Work Management
A11: 1. Your first week in Maximo | B11: 10 | C11: Plans Tab (Planned Work) | D11: =IFERROR(INDEX('Term Map'!$A$2:$A$319,MATCH(C11,'Term Map'!$D$2:$D$319,0)),"Not found") -> M03-009 | E11: =IFERROR(INDEX('Term Map'!$K$2:$K$319,MATCH(C11,'Term Map'!$D$2:$D$319,0)),"") -> Beginner | F11: =IFERROR(INDEX('Term Map'!$B$2:$B$319,MATCH(C11,'Term Map'!$D$2:$D$319,0)),"") -> 03 Work Management
A12: 1. Your first week in Maximo | B12: 11 | C12: Actuals Tab | D12: =IFERROR(INDEX('Term Map'!$A$2:$A$319,MATCH(C12,'Term Map'!$D$2:$D$319,0)),"Not found") -> M03-010 | E12: =IFERROR(INDEX('Term Map'!$K$2:$K$319,MATCH(C12,'Term Map'!$D$2:$D$319,0)),"") -> Beginner | F12: =IFERROR(INDEX('Term Map'!$B$2:$B$319,MATCH(C12,'Term Map'!$D$2:$D$319,0)),"") -> 03 Work Management
A13: 1. Your first week in Maximo | B13: 12 | C13: Job Plan | D13: =IFERROR(INDEX('Term Map'!$A$2:$A$319,MATCH(C13,'Term Map'!$D$2:$D$319,0)),"Not found") -> M04-001 | E13: =IFERROR(INDEX('Term Map'!$K$2:$K$319,MATCH(C13,'Term Map'!$D$2:$D$319,0)),"") -> Beginner | F13: =IFERROR(INDEX('Term Map'!$B$2:$B$319,MATCH(C13,'Term Map'!$D$2:$D$319,0)),"") -> 04 Planning: Job Plans, PMs, Routes and Safety
... A95: 6. Admin and configuration | B95: 16 | C95: Migration Manager | D95: =IFERROR(INDEX('Term Map'!$A$2:$A$319,MATCH(C95,'Term Map'!$D$2:$D$319,0)),"Not found") -> M09-022 | E95: =IFERROR(INDEX('Term Map'!$K$2:$K$319,MATCH(C95,'Term Map'!$D$2:$D$319,0)),"") -> Advanced | F95: =IFERROR(INDEX('Term Map'!$B$2:$B$319,MATCH(C95,'Term Map'!$D$2:$D$319,0)),"") -> 09 Platform, Configuration and Administration

Sheet Sources
A1: Source | B1: What it confirms | C1: URL
A2: IBM Support: Readme for Maximo Application Suite 9.2.0 | B2: MAS 9.2.0 release date (June 25, 2026) and the components included (Core, Manage, Optimizer, IoT, Monitor, Predict, AI Service). | C2: https://www.ibm.com/support/pages/node/7277376
A3: IBM: Licensing in Maximo Application Suite 9.1 (PDF) | B3: Applications covered by MAS licensing, including Manage, Monitor, Health, Predict and Real Estate and Facilities; AppPoints consumption tables. | C3: https://www.ibm.com/docs/en/SSRHPA_cd/pdf/mas_licensing_91.pdf
A4: IBM Support: End of Support Announcement for Maximo 7.6.1 | B4: Base support for Maximo Asset Management 7.6.1.x and related industry solutions ended September 30, 2025. | C4: https://www.ibm.com/support/pages/node/6570953
A5: IBM Support: Maximo 7.6.1.3 last interim fix | B5: Last interim fix for 7.6.1.x on September 30, 2025; support extension needed after that date. | C5: https://www.ibm.com/support/pages/node/7243602
A6: IBM Community: Important update for Maximo users | B6: Extended support for 7.6.x through September 30, 2026; architecture differences between 7.6 and MAS. | C6: https://community.ibm.com/community/user/asset-facilities/discussion/important-update-for-ibm-maximo-users
A7: IBM product update deck (user group, July 2025) | B7: MAS 9.1 GA June 24, 2025; Maximo Assistant, Asset Investment Planning, Real Estate and Facilities, Maintenance Cost Insights; direct upgrade from 7.6.0.10, 7.6.1.2, 7.6.1.3; Mobile Incident Reporter. | C7: https://pacmug.org/wp-content/uploads/2025/07/PacMUGS2505_MaximoApplicationSuiteUpdate_IBM.pdf
A8: IBM Support: MAS AI Service 9.2.x releases | B8: AI Service updates through 2026, including natural language query support for more Manage objects. | C8: https://www.ibm.com/support/pages/node/7270126
A9: Red Hat blog: MAS and OpenShift | B9: MAS application lineup and that MAS runs on Red Hat OpenShift. | C9: https://www.redhat.com/en/blog/ibm-maximo-application-suite-mas-and-red-hat-openshift
A10: IBM Docs (primary reference for every row) | B10: Search 'Maximo Application Suite' at ibm.com/docs and pick your exact version. Use the 'Verify In' column to find the right section. | C10: https://www.ibm.com/docs
